Traceback (most recent call last):
  File "/usr/lib/python3.13/site-packages/libqtile/widget/base.py", line 884, in on_done
    result = future.result()
  File "/usr/lib/python3.13/concurrent/futures/thread.py", line 59, in run
    result = self.fn(*self.args, **self.kwargs)
  File "/usr/lib/python3.13/site-packages/libqtile/widget/generic_poll_text.py", line 38, in poll
    return self.func()
           ~~~~~~~~~^^
  File "/home/luciano/.config/qtile/config.py", line 273, in <lambda>
    func=lambda: subprocess.check_output (
                 ~~~~~~~~~~~~~~~~~~~~~~~~^
        ["~/.config/utiles/network_icon.sh"],
        ^^^^^^^^^^^^^^^^^^^^^^^^^^^^^^^^^^^^^
        universal_newlines=True,
        ^^^^^^^^^^^^^^^^^^^^^^^^
        shell=True
        ^^^^^^^^^^
    ).strip(),
    ^
  File "/usr/lib/python3.13/subprocess.py", line 472, in check_output
    return run(*popenargs, stdout=PIPE, timeout=timeout, check=True,
           ~~~^^^^^^^^^^^^^^^^^^^^^^^^^^^^^^^^^^^^^^^^^^^^^^^^^^^^^^
               **kwargs).stdout
               ^^^^^^^^^
  File "/usr/lib/python3.13/subprocess.py", line 577, in run
    raise CalledProcessError(retcode, process.args,
                             output=stdout, stderr=stderr)
subprocess.CalledProcessError: Command '['~/.config/utiles/network_icon.sh']' returned non-zero exit status 126.
2025-05-22 12:17:52,314 WARNING libqtile base.py:on_done():L899 genpolltext's poll() returned None, not rescheduling
